Workbook

Sheet Raw Data
A1: Measurement number | B1: HART-14 | C1: HART-15 | D1: HART-13 | E1: HART-12 | F1: HART-16 | G1: HART-17 | H1: HART-18 | I1: HART-19 | J1: JACK-11 | K1: JACK-22 | L1: JACK-24 | M1: JACK-25 | N1: JACK-31 | O1: JACK-33 | P1: JACK-34 | Q1: JACK-35 | R1: Elson-23-1 | S1: Elson-23-2 | T1: Elson-23-3 | U1: Elson-26-4 | V1: Elson-24-4 | W1: Elson-26-2 | X1: Elson-23-5 | Y1: Elson-24-2 | Z1: Elson-24-3 | AA1: Elson-24-5 | AB1: Elson-26-1 | AC1: Elson-26-6
A2: 1 | B2: 0.71599563 | D2: 0.71480661 | E2: 0.7586442 | G2: 0.71254323 | H2: 0.70878599 | I2: 0.71010426 | J2: 0.70916749 | K2: 0.71118794 | L2: 0.70809413 | M2: 0.71101453 | N2: 0.71048706 | O2: 0.70348603 | P2: 0.70768721 | Q2: 0.70823238 | R2: 0.70899351 | S2: 0.70909142 | T2: 0.71148507 | U2: 0.71041193 | V2: 0.70701505 | W2: 0.70776425 | X2: 0.70899221 | Y2: 0.70801202 | Z2: 0.7070002 | AA2: 0.70797955 | AB2: 0.70930621 | AC2: 0.70088426
A3: 2 | B3: 0.71450095 | D3: 0.71302116 | E3: 0.74989923 | G3: 0.70993079 | H3: 0.70704991 | I3: 0.70595958 | J3: 0.70747506 | K3: 0.70698717 | L3: 0.70976302 | M3: 0.70730218 | N3: 0.71339894 | O3: 0.71342788 | P3: 0.71100513 | Q3: 0.71041977 | R3: 0.70763333 | S3: 0.71022969 | T3: 0.71349671 | U3: 0.70855243 | V3: 0.71151229 | W3: 0.71080876 | X3: 0.71003044 | Y3: 0.70985172 | Z3: 0.71614517 | AA3: 0.70886871 | AB3: 0.707753 | AC3: 0.70856101
A4: 3 | B4: 0.713199 | D4: 0.71419314 | E4: 0.7359024 | G4: 0.70709486 | H4: 0.71532935 | I4: 0.70789203 | J4: 0.70884637 | K4: 0.70864131 | L4: 0.70893299 | M4: 0.7090377 | N4: 0.70757258 | O4: 0.70737651 | P4: 0.70248183 | Q4: 0.7082752 | R4: 0.71094114 | S4: 0.71296098 | T4: 0.7132432 | U4: 0.70895808 | V4: 0.70866864 | W4: 0.70902187 | X4: 0.70674433 | Y4: 0.70967729 | Z4: 0.71272568 | AA4: 0.70887458 | AB4: 0.70937392 | AC4: 0.70946009
A5: 4 | B5: 0.71267146 | D5: 0.71318867 | E5: 0.73540669 | G5: 0.70951884 | H5: 0.70838904 | I5: 0.71137451 | J5: 0.7091911 | K5: 0.70627026 | L5: 0.71060424 | M5: 0.70900197 | N5: 0.72110898 | O5: 0.70902207 | P5: 0.70742867 | Q5: 0.70792779 | R5: 0.70891797 | S5: 0.70925605 | T5: 0.70345818 | U5: 0.70959143 | V5: 0.70761781 | W5: 0.71014109 | X5: 0.70887996 | Y5: 0.70870295 | Z5: 0.71218406 | AA5: 0.7104303 | AB5: 0.7078607 | AC5: 0.70709583
A6: 5 | B6: 0.71187002 | D6: 0.71424951 | E6: 0.72940867 | G6: 0.70784429 | H6: 0.71190925 | I6: 0.71085645 | J6: 0.70918806 | K6: 0.7062441 | L6: 0.71097433 | M6: 0.70938106 | N6: 0.71231282 | O6: 0.70922658 | P6: 0.70826816 | Q6: 0.71004589 | R6: 0.70751257 | S6: 0.70296972 | T6: 0.71476819 | U6: 0.70950746 | V6: 0.70991025 | W6: 0.70771804 | X6: 0.70966016 | Y6: 0.70866759 | Z6: 0.70327401 | AA6: 0.70922822 | AB6: 0.70947646 | AC6: 0.70970639
A7: 6 | B7: 0.71277939 | D7: 0.71285103 | E7: 0.7278827 | G7: 0.71026663 | H7: 0.70766075 | I7: 0.70951216 | J7: 0.71010364 | K7: 0.71186035 | L7: 0.71017393 | M7: 0.70991768 | N7: 0.70113187 | O7: 0.71043814 | P7: 0.70185803 | Q7: 0.70996091 | R7: 0.71208754 | S7: 0.69514273 | T7: 0.70811325 | U7: 0.70852251 | V7: 0.70910854 | W7: 0.71044484 | X7: 0.70867365 | Y7: 0.70851889 | Z7: 0.70910522 | AA7: 0.70889752 | AB7: 0.71443342 | AC7: 0.70925213
A8: 7 | B8: 0.7126938 | D8: 0.71242823 | E8: 0.73068347 | G8: 0.71081793 | H8: 0.70932035 | I8: 0.71099646 | J8: 0.70867486 | K8: 0.71313508 | L8: 0.70678339 | M8: 0.70801099 | N8: 0.71401173 | O8: 0.70951166 | P8: 0.70565107 | Q8: 0.70965687 | R8: 0.71795121 | S8: 0.71774215 | T8: 0.7047779 | U8: 0.70886971 | V8: 0.70811592 | W8: 0.70814891 | X8: 0.70784728 | Y8: 0.70833144 | Z8: 0.7066991 | AA8: 0.70853916 | AB8: 0.71131115 | AC8: 0.71010447
A9: 8 | B9: 0.71087758 | D9: 0.71218829 | E9: 0.72409446 | G9: 0.7109181 | H9: 0.71116886 | I9: 0.70669428 | J9: 0.70949095 | K9: 0.70509293 | L9: 0.71032529 | M9: 0.70930954 | N9: 0.70908873 | O9: 0.70746643 | P9: 0.71439917 | Q9: 0.70980436 | R9: 0.70458791 | S9: 0.71066277 | T9: 0.70995771 | U9: 0.70846408 | V9: 0.70882608 | W9: 0.70882112 | X9: 0.70892782 | Y9: 0.70926543 | Z9: 0.7062941 | AA9: 0.70955843 | AB9: 0.70801143 | AC9: 0.71040154
A10: 9 | B10: 0.71134986 | D10: 0.71135943 | E10: 0.71877652 | G10: 0.70967202 | H10: 0.70609867 | I10: 0.70899622 | J10: 0.71084552 | K10: 0.70643534 | L10: 0.7081115 | M10: 0.70859968 | N10: 0.7093754 | O10: 0.70884254 | P10: 0.71323875 | Q10: 0.70988647 | R10: 0.71232868 | S10: 0.70487001 | T10: 0.71358804 | U10: 0.708914 | V10: 0.70844249 | W10: 0.70865725 | X10: 0.71053906 | Y10: 0.70741303 | Z10: 0.70433676 | AA10: 0.70899341 | AB10: 0.70932782 | AC10: 0.70889484
A11: 10 | B11: 0.7102823 | D11: 0.71086226 | E11: 0.72091673 | G11: 0.70945212 | H11: 0.70927612 | I11: 0.71257937 | J11: 0.70789368 | K11: 0.70982778 | L11: 0.71047762 | M11: 0.70840488 | N11: 0.714819 | O11: 0.70847303 | P11: 0.70767454 | Q11: 0.7098146 | R11: 0.71055528 | S11: 0.7202388 | T11: 0.70430286 | U11: 0.7096535 | V11: 0.7091867 | W11: 0.70954113 | X11: 0.71056145 | Y11: 0.70889052 | Z11: 0.7011766 | AA11: 0.70875941 | AB11: 0.70851359 | AC11: 0.70965817
A12: 11 | B12: 0.71109492 | D12: 0.71045132 | E12: 0.72619053 | G12: 0.71162059 | H12: 0.70856711 | I12: 0.70796971 | J12: 0.70865714 | K12: 0.70750297 | L12: 0.70893984 | M12: 0.70988938 | N12: 0.70547442 | O12: 0.70944751 | P12: 0.70901041 | Q12: 0.70915364 | R12: 0.71086849 | S12: 0.70103114 | T12: 0.70267561 | U12: 0.70811768 | V12: 0.70974798 | W12: 0.70916045 | X12: 0.71026877 | Y12: 0.71055148 | Z12: 0.71071615 | AA12: 0.70926861 | AB12: 0.70849377 | AC12: 0.70797784
A13: 12 | B13: 0.71097233 | D13: 0.71123171 | E13: 0.71930369 | F13: 0.71032361 | G13: 0.7103946 | H13: 0.71072801 | I13: 0.70217042 | J13: 0.70984957 | K13: 0.70711356 | L13: 0.70814303 | M13: 0.70937987 | N13: 0.70683355 | O13: 0.70934532 | P13: 0.71082663 | Q13: 0.70840364 | R13: 0.70821514 | S13: 0.70750114 | T13: 0.71072713 | U13: 0.70962448 | V13: 0.70897548 | W13: 0.70860714 | X13: 0.70987254 | Y13: 0.70926345 | Z13: 0.70780866 | AA13: 0.70988657 | AB13: 0.70802365 | AC13: 0.70877108
A14: 13 | B14: 0.71059067 | D14: 0.71103013 | E14: 0.72292958 | F14: 0.71074464 | G14: 0.70931214 | H14: 0.70841031 | I14: 0.70899914 | J14: 0.70901895 | K14: 0.70973104 | L14: 0.71010089 | M14: 0.7087122 | N14: 0.71108447 | O14: 0.70890099 | P14: 0.71054634 | Q14: 0.70869587 | R14: 0.70883394 | S14: 0.70771862 | T14: 0.70684907 | U14: 0.70846902 | V14: 0.71016353 | W14: 0.708787 | X14: 0.70880637 | Y14: 0.70929995 | Z14: 0.70449835 | AA14: 0.70957686 | AB14: 0.7102565 | AC14: 0.70970439
A15: 14 | B15: 0.71178173 | D15: 0.71107261 | E15: 0.71778507 | F15: 0.71046896 | G15: 0.70976047 | H15: 0.71043134 | I15: 0.70666522 | J15: 0.70821243 | K15: 0.70609933 | L15: 0.70916437 | M15: 0.70808401 | N15: 0.71255117 | O15: 0.70762197 | P15: 0.70781993 | Q15: 0.70952342 | R15: 0.7092279 | S15: 0.71252688 | T15: 0.70971419 | U15: 0.70907331 | V15: 0.7101096 | W15: 0.70863199 | X15: 0.707948 | Y15: 0.70886639 | Z15: 0.71460394 | AA15: 0.70880618 | AB15: 0.70875341 | AC15: 0.70838169
A16: 15 | B16: 0.71171501 | D16: 0.70989554 | E16: 0.72181798 | F16: 0.71027994 | G16: 0.708906 | H16: 0.71261409 | I16: 0.71172406 | J16: 0.70995036 | K16: 0.71051762 | L16: 0.71121522 | M16: 0.70971943 | N16: 0.70662212 | O16: 0.70883018 | P16: 0.70999843 | Q16: 0.70938928 | R16: 0.70766489 | S16: 0.70799323 | T16: 0.7104494 | U16: 0.70841271 | V16: 0.70959208 | W16: 0.70923233 | X16: 0.70969074 | Y16: 0.7084666 | Z16: 0.71326418 | AA16: 0.70816052 | AB16: 0.71004209 | AC16: 0.70916958
A17: 16 | B17: 0.71035943 | D17: 0.71066449 | E17: 0.71763382 | F17: 0.71020105 | G17: 0.71021487 | H17: 0.71367954 | I17: 0.71571394 | J17: 0.70821775 | K17: 0.70801155 | L17: 0.70817156 | M17: 0.70898236 | N17: 0.70865107 | O17: 0.70888157 | P17: 0.71334183 | Q17: 0.70896045 | R17: 0.70769617 | S17: 0.70765643 | T17: 0.70779801 | U17: 0.7088273 | V17: 0.70880766 | W17: 0.70999907 | X17: 0.70879467 | Y17: 0.70965428 | Z17: 0.71222922 | AA17: 0.70944096 | AB17: 0.70920088 | AC17: 0.70912171
A18: 17 | B18: 0.71119497 | D18: 0.71131311 | E18: 0.71772524 | F18: 0.70949941 | G18: 0.70846603 | H18: 0.70754295 | I18: 0.71077976 | J18: 0.70950556 | K18: 0.70935039 | L18: 0.70822435 | M18: 0.70935813 | N18: 0.7061043 | O18: 0.70897044 | P18: 0.70700137 | Q18: 0.70931224 | R18: 0.70872172 | S18: 0.71188771 | T18: 0.70596371 | U18: 0.7096075 | V18: 0.71011857 | W18: 0.70939746 | X18: 0.70936461 | Y18: 0.70905718 | Z18: 0.71097181 | AA18: 0.70896431 | AB18: 0.70803007 | AC18: 0.70882134
A19: 18 | B19: 0.71066785 | D19: 0.71065754 | E19: 0.71320904 | F19: 0.71006875 | G19: 0.71021767 | H19: 0.70949535 | I19: 0.7075758 | J19: 0.70900989 | K19: 0.70003346 | L19: 0.70902926 | M19: 0.70932804 | N19: 0.71036185 | O19: 0.70905237 | P19: 0.71085966 | Q19: 0.70886406 | R19: 0.7082778 | S19: 0.71084428 | T19: 0.71000353 | U19: 0.70897986 | V19: 0.70939146 | W19: 0.70935143 | X19: 0.70895227 | Y19: 0.70908331 | Z19: 0.70461479 | AA19: 0.70994666 | AB19: 0.70943729 | AC19: 0.7093686
A20: 19 | B20: 0.71087288 | D20: 0.71080795 | E20: 0.71658691 | F20: 0.711135 | G20: 0.7022028 | H20: 0.70926305 | I20: 0.71064402 | J20: 0.70890241 | K20: 0.71582982 | L20: 0.70905559 | M20: 0.7086675 | N20: 0.71125327 | O20: 0.70957836 | P20: 0.70938494 | Q20: 0.7098379 | R20: 0.70832063 | S20: 0.70915897 | T20: 0.70784925 | U20: 0.70932209 | V20: 0.71090589 | W20: 0.70917684 | X20: 0.70960434 | Y20: 0.70842462 | Z20: 0.71105528 | AA20: 0.70920561 | AB20: 0.7081718 | AC20: 0.70957436
A21: 20 | B21: 0.71061834 | D21: 0.70954251 | E21: 0.71422011 | F21: 0.71041071 | G21: 0.70989079 | H21: 0.70707989 | I21: 0.70704542 | J21: 0.70964562 | K21: 0.70123445 | L21: 0.70988995 | M21: 0.70898243 | N21: 0.71152611 | O21: 0.70969457 | P21: 0.71089155 | Q21: 0.70859628 | R21: 0.70915233 | S21: 0.70859912 | T21: 0.70675424 | U21: 0.70926181 | V21: 0.70898606 | W21: 0.70770533 | X21: 0.70913101 | Y21: 0.70894687 | Z21: 0.70965111 | AA21: 0.70958742 | AB21: 0.7093435 | AC21: 0.71013703
A22: 21 | B22: 0.71076311 | D22: 0.70989727 | E22: 0.71564024 | F22: 0.71043096 | G22: 0.7074492 | H22: 0.71030893 | I22: 0.70785838 | J22: 0.70933288 | K22: 0.70793876 | L22: 0.70867587 | M22: 0.70851656 | N22: 0.70090858 | O22: 0.70869487 | P22: 0.71014606 | Q22: 0.70865986 | R22: 0.7104275 | S22: 0.70926741 | T22: 0.70846867 | U22: 0.70913021 | V22: 0.70944614 | W22: 0.70974944 | X22: 0.70845017 | Y22: 0.7087756 | Z22: 0.70942116 | AA22: 0.70765069 | AB22: 0.70898581 | AC22: 0.70988094
A23: 22 | B23: 0.70993356 | D23: 0.71030184 | E23: 0.71552454 | F23: 0.71075944 | G23: 0.7096858 | H23: 0.70900969 | I23: 0.70881 | J23: 0.70789969 | K23: 0.70739031 | L23: 0.7082059 | M23: 0.70932865 | N23: 0.70648097 | O23: 0.70860633 | P23: 0.70076162 | Q23: 0.70914223 | R23: 0.70586609 | S23: 0.70979715 | T23: 0.70975505 | U23: 0.70854396 | V23: 0.70959258 | W23: 0.7094156 | X23: 0.71023461 | Y23: 0.7090551 | Z23: 0.70841999 | AA23: 0.70929259 | AB23: 0.70951113 | AC23: 0.7089574
A24: 23 | B24: 0.7112046 | D24: 0.70974897 | E24: 0.7181569 | F24: 0.71116245 | G24: 0.70919016 | H24: 0.70756421 | I24: 0.70671169 | J24: 0.70885172 | K24: 0.70728198 | L24: 0.70878473 | M24: 0.70887326 | N24: 0.70490598 | O24: 0.70938671 | P24: 0.70829 | Q24: 0.70921994 | R24: 0.70845389 | S24: 0.70946133 | T24: 0.71401628 | U24: 0.7091397 | V24: 0.70949223 | W24: 0.70937825 | X24: 0.70748586 | Y24: 0.70969613 | Z24: 0.71024336 | AA24: 0.70962096 | AB24: 0.70889451 | AC24: 0.70829887
... A38: 37 | B38: 0.71090299 | D38: 0.71066335 | E38: 0.71477542 | F38: 0.7094851 | G38: 0.71132098 | H38: 0.7089998 | I38: 0.70973293 | J38: 0.70882674 | K38: 0.71328813 | L38: 0.70854273 | M38: 0.7090809 | N38: 0.71358533 | O38: 0.70877965 | P38: 0.71269223 | Q38: 0.70817347 | R38: 0.70867585 | S38: 0.70978483 | T38: 0.7186582 | U38: 0.70917592 | V38: 0.70929103 | W38: 0.70960328 | X38: 0.70926166 | Y38: 0.70880326 | Z38: 0.7087569 | AA38: 0.70820937 | AB38: 0.70953202 | AC38: 0.70913598
A39: 38 | B39: 0.71018415 | C39: 0.713014 | D39: 0.70952667 | E39: 0.71552193 | F39: 0.71095924 | G39: 0.70879583 | H39: 0.70894328 | I39: 0.70932038 | J39: 0.70929187 | K39: 0.71096644 | L39: 0.70889652 | M39: 0.70918399 | N39: 0.70971909 | O39: 0.70881785 | P39: 0.70988616 | Q39: 0.70912689 | R39: 0.70965618 | S39: 0.70875021 | T39: 0.70450017 | U39: 0.70874315 | V39: 0.70878327 | W39: 0.70892078 | X39: 0.7094941 | Y39: 0.7089254 | Z39: 0.70890736 | AA39: 0.70962812 | AB39: 0.70961134 | AC39: 0.70905207
A40: 39 | B40: 0.71001287 | C40: 0.71210173 | D40: 0.71008695 | E40: 0.71365713 | F40: 0.70903087 | G40: 0.70859796 | H40: 0.70874263 | I40: 0.70957477 | J40: 0.70847049 | K40: 0.71392396 | L40: 0.70953566 | M40: 0.70890994 | N40: 0.71223141 | O40: 0.70922097 | P40: 0.71081516 | Q40: 0.70909312 | R40: 0.71000596 | S40: 0.70884358 | T40: 0.7078884 | U40: 0.70998722 | V40: 0.70850723 | W40: 0.70963767 | X40: 0.70867629 | Y40: 0.70974457 | Z40: 0.70937787 | AA40: 0.70892987 | AB40: 0.70885371 | AC40: 0.70896426
A41: 40 | B41: 0.70937143 | C41: 0.71259414 | D41: 0.70989443 | E41: 0.71471204 | F41: 0.7096586 | G41: 0.71120314 | H41: 0.70895625 | I41: 0.70904002 | J41: 0.70876664 | K41: 0.70699773 | L41: 0.70855599 | M41: 0.70863903 | N41: 0.70927151 | O41: 0.70897249 | P41: 0.71123228 | Q41: 0.70901147 | R41: 0.71024298 | S41: 0.70873155 | T41: 0.71081217 | U41: 0.70887552 | V41: 0.70866995 | W41: 0.70895131 | X41: 0.70965522 | Y41: 0.70888512 | Z41: 0.70888547 | AA41: 0.70971692 | AB41: 0.70869114 | AC41: 0.70959422
A42: 41 | B42: 0.71042744 | C42: 0.71219073 | D42: 0.70993723 | E42: 0.71445586 | F42: 0.71040401 | G42: 0.71064922 | H42: 0.70965174 | I42: 0.7091591 | J42: 0.70903889 | K42: 0.7100136 | L42: 0.70929907 | M42: 0.7096146 | N42: 0.70980679 | O42: 0.7091801 | P42: 0.70926399 | Q42: 0.7093237 | R42: 0.70932314 | S42: 0.70884303 | T42: 0.74071056 | U42: 0.70899928 | V42: 0.70878982 | W42: 0.70946307 | X42: 0.70922028 | Y42: 0.70895256 | Z42: 0.70943309 | AA42: 0.70956568 | AB42: 0.70892639 | AC42: 0.70892067
A43: 42 | B43: 0.70929775 | C43: 0.70991401 | D43: 0.71011516 | E43: 0.7135827 | F43: 0.71034988 | G43: 0.70635441 | H43: 0.70870408 | I43: 0.70905996 | J43: 0.7084273 | K43: 0.70612073 | L43: 0.70872643 | M43: 0.70900382 | N43: 0.71424952 | O43: 0.70932366 | P43: 0.71157334 | Q43: 0.70932343 | R43: 0.70992458 | S43: 0.70941492 | T43: 0.70637211 | U43: 0.70986118 | V43: 0.70924277 | W43: 0.70868334 | X43: 0.71012076 | Y43: 0.70967058 | Z43: 0.70898983 | AA43: 0.70952145 | AB43: 0.70902313 | AC43: 0.70877292
A44: 43 | B44: 0.71022198 | C44: 0.71119752 | D44: 0.70974292 | E44: 0.71452785 | F44: 0.70884915 | G44: 0.71056758 | H44: 0.70944993 | I44: 0.70935508 | J44: 0.70866883 | K44: 0.70865211 | L44: 0.70787235 | M44: 0.70981903 | N44: 0.70926499 | O44: 0.70905676 | P44: 0.70853291 | Q44: 0.70925853 | R44: 0.70883268 | S44: 0.70935108 | T44: 0.70767502 | U44: 0.70931405 | V44: 0.70874555 | W44: 0.70930661 | X44: 0.70903965 | Y44: 0.70932043 | Z44: 0.70949214 | AA44: 0.70851914 | AB44: 0.70976315 | AC44: 0.70880011
A45: 44 | B45: 0.70973202 | C45: 0.71026647 | D45: 0.71009828 | E45: 0.71763085 | F45: 0.70946879 | G45: 0.70965168 | H45: 0.70987394 | I45: 0.70960389 | J45: 0.70872688 | K45: 0.70822362 | L45: 0.70949527 | M45: 0.70859582 | N45: 0.70846173 | O45: 0.70967429 | P45: 0.70973801 | Q45: 0.70921745 | R45: 0.70934541 | S45: 0.70980301 | T45: 0.71534297 | U45: 0.70898953 | V45: 0.7081241 | W45: 0.70966644 | X45: 0.70966933 | Y45: 0.70899769 | Z45: 0.70876973 | AA45: 0.70943858 | AB45: 0.70908084 | AC45: 0.70903334
A46: 45 | B46: 0.70976012 | C46: 0.71071237 | D46: 0.71009501 | E46: 0.71687303 | F46: 0.71008136 | G46: 0.70968484 | H46: 0.70888035 | I46: 0.70903253 | J46: 0.70888438 | K46: 0.70705331 | L46: 0.70885501 | M46: 0.7093341 | N46: 0.71221736 | O46: 0.70861506 | P46: 0.70836923 | Q46: 0.70828879 | R46: 0.70957782 | S46: 0.70883552 | T46: 0.71884003 | U46: 0.70989863 | V46: 0.70903785 | W46: 0.70935539 | X46: 0.7091756 | Y46: 0.70948144 | Z46: 0.70873437 | AA46: 0.7091131 | AB46: 0.70891681 | AC46: 0.70891353
A47: 46 | B47: 0.70992605 | C47: 0.7102746 | D47: 0.70966361 | E47: 0.71492658 | F47: 0.71028768 | G47: 0.70453518 | H47: 0.70943371 | I47: 0.70895634 | J47: 0.70815782 | K47: 0.71003586 | L47: 0.70995774 | M47: 0.70917208 | N47: 0.70862655 | O47: 0.70927312 | P47: 0.71069595 | Q47: 0.70960214 | R47: 0.71028937 | S47: 0.71106457 | T47: 0.71020071 | U47: 0.70881235 | V47: 0.70926892 | W47: 0.71005668 | X47: 0.70935308 | Y47: 0.70979684 | Z47: 0.70922929 | AA47: 0.71031576 | AB47: 0.70964741 | AC47: 0.70969049
A48: 47 | B48: 0.70953321 | C48: 0.71049254 | D48: 0.70982548 | E48: 0.71473778 | F48: 0.70924544 | G48: 0.71025988 | H48: 0.70873253 | I48: 0.71055209 | J48: 0.70846965 | K48: 0.70742878 | L48: 0.70898967 | M48: 0.70912865 | N48: 0.71080754 | O48: 0.70911847 | P48: 0.7071547 | Q48: 0.70968405 | R48: 0.70847396 | S48: 0.70925998 | T48: 0.71006172 | U48: 0.70922031 | V48: 0.70770451 | W48: 0.70948434 | X48: 0.7093297 | Y48: 0.70947521 | Z48: 0.70891176 | AA48: 0.7092178 | AB48: 0.709458 | AC48: 0.70957013
A49: 48 | B49: 0.70990113 | C49: 0.70995297 | D49: 0.70950344 | E49: 0.71686726 | F49: 0.71013624 | G49: 0.70510188 | H49: 0.70948269 | I49: 0.70784127 | J49: 0.70910028 | K49: 0.71035557 | L49: 0.70873417 | M49: 0.70898092 | N49: 0.71037469 | O49: 0.70881978 | P49: 0.71086684 | Q49: 0.70879417 | R49: 0.71046992 | S49: 0.70872494 | T49: 0.70979952 | U49: 0.70864288 | V49: 0.70845338 | W49: 0.70893257 | X49: 0.70952082 | Y49: 0.70920576 | Z49: 0.70907193 | AA49: 0.70918175 | AB49: 0.70899224 | AC49: 0.70882015
A50: 49 | B50: 0.71048169 | C50: 0.71018619 | D50: 0.70974738 | E50: 0.71552101 | F50: 0.70921731 | G50: 0.70748561 | H50: 0.70860078 | I50: 0.70879642 | J50: 0.70862395 | K50: 0.70641567 | L50: 0.70888169 | M50: 0.70961064 | N50: 0.71175361 | O50: 0.71019822 | P50: 0.71246827 | Q50: 0.70861573 | R50: 0.7092987 | S50: 0.70946427 | T50: 0.71034087 | U50: 0.70877514 | V50: 0.7084034 | W50: 0.71028026 | X50: 0.70956784 | Y50: 0.7091757 | Z50: 0.70887928 | AA50: 0.70956238 | AB50: 0.70892319 | AC50: 0.70850454
... A204: 203 | B204: 0.70901703 | C204: 0.71136522 | D204: 0.70853844 | E204: 0.70948408 | F204: 0.70988465 | G204: 0.70785306 | H204: 0.70783994 | I204: 0.7096356 | J204: 0.70782858 | K204: 0.70853137 | L204: 0.70873964 | M204: 0.70898786 | N204: 0.70881951 | O204: 0.70810666 | P204: 0.70898146 | Q204: 0.70879233 | R204: 0.70916702 | S204: 0.70869204 | T204: 0.70789402 | U204: 0.70805346 | V204: 0.70922483 | W204: 0.70695265 | X204: 0.71064416 | Y204: 0.7092395 | Z204: 0.70943115 | AA204: 0.70859745 | AB204: 0.70914159 | AC204: 0.70738415
A205: 204 | B205: 0.70880733 | C205: 0.70966682 | D205: 0.70915408 | E205: 0.70878755 | F205: 0.71027419 | G205: 0.70854502 | H205: 0.70782227 | I205: 0.70865366 | K205: 0.70873266 | L205: 0.70844933 | M205: 0.70887973 | N205: 0.70987122 | O205: 0.70801119 | P205: 0.70911407 | Q205: 0.70863276 | R205: 0.70966169 | S205: 0.70877996 | T205: 0.70743873 | U205: 0.70900803 | V205: 0.70984918 | W205: 0.70750707 | X205: 0.70777669 | Y205: 0.70984168 | Z205: 0.70878534 | AA205: 0.70832183 | AB205: 0.70970366 | AC205: 0.70823881
A206: 205 | B206: 0.71002477 | C206: 0.7089369 | D206: 0.70866197 | E206: 0.70960734 | F206: 0.70884642 | G206: 0.70846033 | H206: 0.70787236 | I206: 0.70847365 | K206: 0.70876009 | L206: 0.70850491 | M206: 0.70847026 | N206: 0.70836172 | O206: 0.70758671 | P206: 0.70989887 | Q206: 0.7086409 | R206: 0.70930904 | S206: 0.70910386 | T206: 0.71019352 | U206: 0.70848288 | V206: 0.70830585 | W206: 0.70872378 | X206: 0.70879731 | Y206: 0.70850481 | Z206: 0.70860808 | AA206: 0.70816262 | AB206: 0.70832686 | AC206: 0.70839526
...

Sheet 7 Point Average
A1: Measurement Number | B1: ='Raw Data'!B1 -> HART-14 | C1: ='Raw Data'!C1 -> HART-15 | D1: ='Raw Data'!D1 -> HART-13 | E1: ='Raw Data'!E1 -> HART-12 | F1: ='Raw Data'!F1 -> HART-16 | G1: ='Raw Data'!G1 -> HART-17 | H1: ='Raw Data'!H1 -> HART-18 | I1: ='Raw Data'!I1 -> HART-19 | ... BF1: ='Raw Data'!BF1 -> 0
A2: ='Raw Data'!A2 -> 1 | B2: =AVERAGE('Raw Data'!C2:C8) -> #DIV/0! | C2: =AVERAGE('Raw Data'!D2:D8) -> 0.71353405 | D2: =AVERAGE('Raw Data'!E2:E8) -> 0.73826105 | E2: =AVERAGE('Raw Data'!F2:F8) -> #DIV/0! | F2: =AVERAGE('Raw Data'!G2:G8) -> 0.70971666 | G2: =AVERAGE('Raw Data'!H2:H8) -> 0.7097778 | H2: =AVERAGE('Raw Data'!I2:I8) -> 0.70952792 | I2: =AVERAGE('Raw Data'!J2:J8) -> 0.70894951 | ... BB2: =AVERAGE('Raw Data'!BC2:BC8) -> #DIV/0! | BC2: =AVERAGE('Raw Data'!AW2:AW8) -> #DIV/0! | BD2: =AVERAGE('Raw Data'!AX2:AX8) -> #DIV/0! | BE2: =AVERAGE('Raw Data'!AY2:AY8) -> #DIV/0! | BF2: =AVERAGE('Raw Data'!AZ2:AZ8) -> #DIV/0!
A3: ='Raw Data'!A3 -> 2 | B3: =AVERAGE('Raw Data'!C3:C9) -> #DIV/0! | C3: =AVERAGE('Raw Data'!D3:D9) -> 0.71316 | D3: =AVERAGE('Raw Data'!E3:E9) -> 0.73332538 | E3: =AVERAGE('Raw Data'!F3:F9) -> #DIV/0! | F3: =AVERAGE('Raw Data'!G3:G9) -> 0.70948449 | G3: =AVERAGE('Raw Data'!H3:H9) -> 0.71011821 | H3: =AVERAGE('Raw Data'!I3:I9) -> 0.70904078 | I3: =AVERAGE('Raw Data'!J3:J9) -> 0.70899572 | ... BB3: =AVERAGE('Raw Data'!BC3:BC9) -> #DIV/0! | BC3: =AVERAGE('Raw Data'!AW3:AW9) -> #DIV/0! | BD3: =AVERAGE('Raw Data'!AX3:AX9) -> #DIV/0! | BE3: =AVERAGE('Raw Data'!AY3:AY9) -> #DIV/0! | BF3: =AVERAGE('Raw Data'!AZ3:AZ9) -> #DIV/0!
A4: ='Raw Data'!A4 -> 3 | B4: =AVERAGE('Raw Data'!C4:C10) -> #DIV/0! | C4: =AVERAGE('Raw Data'!D4:D10) -> 0.71292261 | D4: =AVERAGE('Raw Data'!E4:E10) -> 0.72887927 | E4: =AVERAGE('Raw Data'!F4:F10) -> #DIV/0! | F4: =AVERAGE('Raw Data'!G4:G10) -> 0.70944753 | G4: =AVERAGE('Raw Data'!H4:H10) -> 0.70998232 | H4: =AVERAGE('Raw Data'!I4:I10) -> 0.70947459 | I4: =AVERAGE('Raw Data'!J4:J10) -> 0.70947721 | ... BB4: =AVERAGE('Raw Data'!BC4:BC10) -> #DIV/0! | BC4: =AVERAGE('Raw Data'!AW4:AW10) -> #DIV/0! | BD4: =AVERAGE('Raw Data'!AX4:AX10) -> #DIV/0! | BE4: =AVERAGE('Raw Data'!AY4:AY10) -> #DIV/0! | BF4: =AVERAGE('Raw Data'!AZ4:AZ10) -> #DIV/0!
A5: ='Raw Data'!A5 -> 4 | B5: =AVERAGE('Raw Data'!C5:C11) -> #DIV/0! | C5: =AVERAGE('Raw Data'!D5:D11) -> 0.71244677 | D5: =AVERAGE('Raw Data'!E5:E11) -> 0.72673846 | E5: =AVERAGE('Raw Data'!F5:F11) -> #DIV/0! | F5: =AVERAGE('Raw Data'!G5:G11) -> 0.70978428 | G5: =AVERAGE('Raw Data'!H5:H11) -> 0.70911758 | H5: =AVERAGE('Raw Data'!I5:I11) -> 0.71014421 | I5: =AVERAGE('Raw Data'!J5:J11) -> 0.70934112 | ... BB5: =AVERAGE('Raw Data'!BC5:BC11) -> #DIV/0! | BC5: =AVERAGE('Raw Data'!AW5:AW11) -> #DIV/0! | BD5: =AVERAGE('Raw Data'!AX5:AX11) -> #DIV/0! | BE5: =AVERAGE('Raw Data'!AY5:AY11) -> #DIV/0! | BF5: =AVERAGE('Raw Data'!AZ5:AZ11) -> #DIV/0!
A6: ='Raw Data'!A6 -> 5 | B6: =AVERAGE('Raw Data'!C6:C12) -> #DIV/0! | C6: =AVERAGE('Raw Data'!D6:D12) -> 0.71205572 | D6: =AVERAGE('Raw Data'!E6:E12) -> 0.72542187 | E6: =AVERAGE('Raw Data'!F6:F12) -> #DIV/0! | F6: =AVERAGE('Raw Data'!G6:G12) -> 0.71008453 | G6: =AVERAGE('Raw Data'!H6:H12) -> 0.70914301 | H6: =AVERAGE('Raw Data'!I6:I12) -> 0.70965781 | I6: =AVERAGE('Raw Data'!J6:J12) -> 0.70926484 | ... BB6: =AVERAGE('Raw Data'!BC6:BC12) -> #DIV/0! | BC6: =AVERAGE('Raw Data'!AW6:AW12) -> #DIV/0! | BD6: =AVERAGE('Raw Data'!AX6:AX12) -> #DIV/0! | BE6: =AVERAGE('Raw Data'!AY6:AY12) -> #DIV/0! | BF6: =AVERAGE('Raw Data'!AZ6:AZ12) -> #DIV/0!
A7: ='Raw Data'!A7 -> 6 | B7: =AVERAGE('Raw Data'!C7:C13) -> #DIV/0! | C7: =AVERAGE('Raw Data'!D7:D13) -> 0.71162461 | D7: =AVERAGE('Raw Data'!E7:E13) -> 0.7239783 | E7: =AVERAGE('Raw Data'!F7:F13) -> 0.71032361 | F7: =AVERAGE('Raw Data'!G7:G13) -> 0.71044886 | G7: =AVERAGE('Raw Data'!H7:H13) -> 0.70897426 | H7: =AVERAGE('Raw Data'!I7:I13) -> 0.70841695 | I7: =AVERAGE('Raw Data'!J7:J13) -> 0.70935934 | ... BB7: =AVERAGE('Raw Data'!BC7:BC13) -> #DIV/0! | BC7: =AVERAGE('Raw Data'!AW7:AW13) -> #DIV/0! | BD7: =AVERAGE('Raw Data'!AX7:AX13) -> #DIV/0! | BE7: =AVERAGE('Raw Data'!AY7:AY13) -> #DIV/0! | BF7: =AVERAGE('Raw Data'!AZ7:AZ13) -> #DIV/0!
A8: ='Raw Data'!A8 -> 7 | B8: =AVERAGE('Raw Data'!C8:C14) -> #DIV/0! | C8: =AVERAGE('Raw Data'!D8:D14) -> 0.71136448 | D8: =AVERAGE('Raw Data'!E8:E14) -> 0.72327071 | E8: =AVERAGE('Raw Data'!F8:F14) -> 0.71053412 | F8: =AVERAGE('Raw Data'!G8:G14) -> 0.7103125 | G8: =AVERAGE('Raw Data'!H8:H14) -> 0.70908135 | H8: =AVERAGE('Raw Data'!I8:I14) -> 0.70834366 | I8: =AVERAGE('Raw Data'!J8:J14) -> 0.70920438 | ... BB8: =AVERAGE('Raw Data'!BC8:BC14) -> #DIV/0! | BC8: =AVERAGE('Raw Data'!AW8:AW14) -> #DIV/0! | BD8: =AVERAGE('Raw Data'!AX8:AX14) -> #DIV/0! | BE8: =AVERAGE('Raw Data'!AY8:AY14) -> #DIV/0! | BF8: =AVERAGE('Raw Data'!AZ8:AZ14) -> #DIV/0!
A9: ='Raw Data'!A9 -> 8 | B9: =AVERAGE('Raw Data'!C9:C15) -> #DIV/0! | C9: =AVERAGE('Raw Data'!D9:D15) -> 0.71117082 | D9: =AVERAGE('Raw Data'!E9:E15) -> 0.72142808 | E9: =AVERAGE('Raw Data'!F9:F15) -> 0.7105124 | F9: =AVERAGE('Raw Data'!G9:G15) -> 0.71016143 | G9: =AVERAGE('Raw Data'!H9:H15) -> 0.70924006 | H9: =AVERAGE('Raw Data'!I9:I15) -> 0.70772491 | I9: =AVERAGE('Raw Data'!J9:J15) -> 0.70913832 | ... BB9: =AVERAGE('Raw Data'!BC9:BC15) -> #DIV/0! | BC9: =AVERAGE('Raw Data'!AW9:AW15) -> #DIV/0! | BD9: =AVERAGE('Raw Data'!AX9:AX15) -> #DIV/0! | BE9: =AVERAGE('Raw Data'!AY9:AY15) -> #DIV/0! | BF9: =AVERAGE('Raw Data'!AZ9:AZ15) -> #DIV/0!
A10: ='Raw Data'!A10 -> 9 | B10: =AVERAGE('Raw Data'!C10:C16) -> #DIV/0! | C10: =AVERAGE('Raw Data'!D10:D16) -> 0.71084328 | D10: =AVERAGE('Raw Data'!E10:E16) -> 0.72110287 | E10: =AVERAGE('Raw Data'!F10:F16) -> 0.71045429 | F10: =AVERAGE('Raw Data'!G10:G16) -> 0.70987399 | G10: =AVERAGE('Raw Data'!H10:H16) -> 0.70944652 | H10: =AVERAGE('Raw Data'!I10:I16) -> 0.70844345 | I10: =AVERAGE('Raw Data'!J10:J16) -> 0.70920395 | ... BB10: =AVERAGE('Raw Data'!BC10:BC16) -> #DIV/0! | BC10: =AVERAGE('Raw Data'!AW10:AW16) -> #DIV/0! | BD10: =AVERAGE('Raw Data'!AX10:AX16) -> #DIV/0! | BE10: =AVERAGE('Raw Data'!AY10:AY16) -> #DIV/0! | BF10: =AVERAGE('Raw Data'!AZ10:AZ16) -> #DIV/0!
A11: ='Raw Data'!A11 -> 10 | B11: =AVERAGE('Raw Data'!C11:C17) -> #DIV/0! | C11: =AVERAGE('Raw Data'!D11:D17) -> 0.71074401 | D11: =AVERAGE('Raw Data'!E11:E17) -> 0.72093963 | E11: =AVERAGE('Raw Data'!F11:F17) -> 0.71040364 | F11: =AVERAGE('Raw Data'!G11:G17) -> 0.70995154 | G11: =AVERAGE('Raw Data'!H11:H17) -> 0.7105295 | H11: =AVERAGE('Raw Data'!I11:I17) -> 0.70940312 | I11: =AVERAGE('Raw Data'!J11:J17) -> 0.70882855 | ... BB11: =AVERAGE('Raw Data'!BC11:BC17) -> #DIV/0! | BC11: =AVERAGE('Raw Data'!AW11:AW17) -> #DIV/0! | BD11: =AVERAGE('Raw Data'!AX11:AX17) -> #DIV/0! | BE11: =AVERAGE('Raw Data'!AY11:AY17) -> #DIV/0! | BF11: =AVERAGE('Raw Data'!AZ11:AZ17) -> #DIV/0!
A12: ='Raw Data'!A12 -> 11 | B12: =AVERAGE('Raw Data'!C12:C18) -> #DIV/0! | C12: =AVERAGE('Raw Data'!D12:D18) -> 0.71080841 | D12: =AVERAGE('Raw Data'!E12:E18) -> 0.7204837 | E12: =AVERAGE('Raw Data'!F12:F18) -> 0.71025293 | F12: =AVERAGE('Raw Data'!G12:G18) -> 0.70981067 | G12: =AVERAGE('Raw Data'!H12:H18) -> 0.71028191 | H12: =AVERAGE('Raw Data'!I12:I18) -> 0.70914603 | I12: =AVERAGE('Raw Data'!J12:J18) -> 0.70905882 | ... BB12: =AVERAGE('Raw Data'!BC12:BC18) -> #DIV/0! | BC12: =AVERAGE('Raw Data'!AW12:AW18) -> #DIV/0! | BD12: =AVERAGE('Raw Data'!AX12:AX18) -> #DIV/0! | BE12: =AVERAGE('Raw Data'!AY12:AY18) -> #DIV/0! | BF12: =AVERAGE('Raw Data'!AZ12:AZ18) -> #DIV/0!
A13: ='Raw Data'!A13 -> 12 | B13: =AVERAGE('Raw Data'!C13:C19) -> #DIV/0! | C13: =AVERAGE('Raw Data'!D13:D19) -> 0.71083788 | D13: =AVERAGE('Raw Data'!E13:E19) -> 0.7186292 | E13: =AVERAGE('Raw Data'!F13:F19) -> 0.71022662 | F13: =AVERAGE('Raw Data'!G13:G19) -> 0.70961025 | G13: =AVERAGE('Raw Data'!H13:H19) -> 0.71041451 | H13: =AVERAGE('Raw Data'!I13:I19) -> 0.70908976 | I13: =AVERAGE('Raw Data'!J13:J19) -> 0.70910922 | ... BB13: =AVERAGE('Raw Data'!BC13:BC19) -> #DIV/0! | BC13: =AVERAGE('Raw Data'!AW13:AW19) -> #DIV/0! | BD13: =AVERAGE('Raw Data'!AX13:AX19) -> #DIV/0! | BE13: =AVERAGE('Raw Data'!AY13:AY19) -> #DIV/0! | BF13: =AVERAGE('Raw Data'!AZ13:AZ19) -> #DIV/0!
... A107: ='Raw Data'!A107 -> 106 | B107: =AVERAGE('Raw Data'!C107:C113) -> 0.70930874 | C107: =AVERAGE('Raw Data'!D107:D113) -> 0.7098652 | D107: =AVERAGE('Raw Data'!E107:E113) -> 0.71002592 | E107: =AVERAGE('Raw Data'!F107:F113) -> 0.70970487 | F107: =AVERAGE('Raw Data'!G107:G113) -> 0.70877238 | G107: =AVERAGE('Raw Data'!H107:H113) -> 0.7080848 | H107: =AVERAGE('Raw Data'!I107:I113) -> 0.7080228 | I107: =AVERAGE('Raw Data'!J107:J113) -> 0.7087172 | ... BB107: =AVERAGE('Raw Data'!BC107:BC113) -> #DIV/0! | BC107: =AVERAGE('Raw Data'!AW107:AW113) -> #DIV/0! | BD107: =AVERAGE('Raw Data'!AX107:AX113) -> #DIV/0! | BE107: =AVERAGE('Raw Data'!AY107:AY113) -> #DIV/0! | BF107: =AVERAGE('Raw Data'!AZ107:AZ113) -> #DIV/0!
A108: ='Raw Data'!A108 -> 107 | B108: =AVERAGE('Raw Data'!C108:C114) -> 0.70939833 | C108: =AVERAGE('Raw Data'!D108:D114) -> 0.7097847 | D108: =AVERAGE('Raw Data'!E108:E114) -> 0.71000203 | E108: =AVERAGE('Raw Data'!F108:F114) -> 0.70975261 | F108: =AVERAGE('Raw Data'!G108:G114) -> 0.70894792 | G108: =AVERAGE('Raw Data'!H108:H114) -> 0.70788396 | H108: =AVERAGE('Raw Data'!I108:I114) -> 0.70798066 | I108: =AVERAGE('Raw Data'!J108:J114) -> 0.70843713 | ... BB108: =AVERAGE('Raw Data'!BC108:BC114) -> #DIV/0! | BC108: =AVERAGE('Raw Data'!AV108:AV114) -> #DIV/0! | BD108: =AVERAGE('Raw Data'!AW108:AW114) -> #DIV/0! | BE108: =AVERAGE('Raw Data'!AX108:AX114) -> #DIV/0! | BF108: =AVERAGE('Raw Data'!AY108:AY114) -> #DIV/0!
A109: ='Raw Data'!A109 -> 108 | B109: =AVERAGE('Raw Data'!C109:C115) -> 0.70948006 | C109: =AVERAGE('Raw Data'!D109:D115) -> 0.70970928 | D109: =AVERAGE('Raw Data'!E109:E115) -> 0.71042189 | E109: =AVERAGE('Raw Data'!F109:F115) -> 0.70968458 | F109: =AVERAGE('Raw Data'!G109:G115) -> 0.70898736 | G109: =AVERAGE('Raw Data'!H109:H115) -> 0.70785112 | H109: =AVERAGE('Raw Data'!I109:I115) -> 0.70801388 | I109: =AVERAGE('Raw Data'!J109:J115) -> 0.70860713 | ... BB109: =AVERAGE('Raw Data'!BC109:BC115) -> #DIV/0! | BC109: =AVERAGE('Raw Data'!AV109:AV115) -> #DIV/0! | BD109: =AVERAGE('Raw Data'!AW109:AW115) -> #DIV/0! | BE109: =AVERAGE('Raw Data'!AX109:AX115) -> #DIV/0! | BF109: =AVERAGE('Raw Data'!AY109:AY115) -> #DIV/0!
A110: ='Raw Data'!A110 -> 109 | B110: =AVERAGE('Raw Data'!C110:C116) -> 0.70941263 | C110: =AVERAGE('Raw Data'!D110:D116) -> 0.70961088 | D110: =AVERAGE('Raw Data'!E110:E116) -> 0.71028412 | E110: =AVERAGE('Raw Data'!F110:F116) -> 0.70954661 | F110: =AVERAGE('Raw Data'!G110:G116) -> 0.70891983 | G110: =AVERAGE('Raw Data'!H110:H116) -> 0.70783636 | H110: =AVERAGE('Raw Data'!I110:I116) -> 0.70790693 | I110: =AVERAGE('Raw Data'!J110:J116) -> 0.70860298 | ... BB110: =AVERAGE('Raw Data'!BC110:BC116) -> #DIV/0! | BC110: =AVERAGE('Raw Data'!AV110:AV116) -> #DIV/0! | BD110: =AVERAGE('Raw Data'!AW110:AW116) -> #DIV/0! | BE110: =AVERAGE('Raw Data'!AX110:AX116) -> #DIV/0! | BF110: =AVERAGE('Raw Data'!AY110:AY116) -> #DIV/0!
A111: ='Raw Data'!A111 -> 110 | B111: =AVERAGE('Raw Data'!C111:C117) -> 0.70949948 | C111: =AVERAGE('Raw Data'!D111:D117) -> 0.70960483 | D111: =AVERAGE('Raw Data'!E111:E117) -> 0.71027371 | E111: =AVERAGE('Raw Data'!F111:F117) -> 0.70950132 | F111: =AVERAGE('Raw Data'!G111:G117) -> 0.70908509 | G111: =AVERAGE('Raw Data'!H111:H117) -> 0.70789082 | H111: =AVERAGE('Raw Data'!I111:I117) -> 0.70805918 | I111: =AVERAGE('Raw Data'!J111:J117) -> 0.708444 | ... BB111: =AVERAGE('Raw Data'!BC111:BC117) -> #DIV/0! | BC111: =AVERAGE('Raw Data'!AV111:AV117) -> #DIV/0! | BD111: =AVERAGE('Raw Data'!AW111:AW117) -> #DIV/0! | BE111: =AVERAGE('Raw Data'!AX111:AX117) -> #DIV/0! | BF111: =AVERAGE('Raw Data'!AY111:AY117) -> #DIV/0!
A112: ='Raw Data'!A112 -> 111 | B112: =AVERAGE('Raw Data'!C112:C118) -> 0.70978085 | C112: =AVERAGE('Raw Data'!D112:D118) -> 0.7095228 | D112: =AVERAGE('Raw Data'!E112:E118) -> 0.71032509 | E112: =AVERAGE('Raw Data'!F112:F118) -> 0.70953945 | F112: =AVERAGE('Raw Data'!G112:G118) -> 0.70887037 | G112: =AVERAGE('Raw Data'!H112:H118) -> 0.70807671 | H112: =AVERAGE('Raw Data'!I112:I118) -> 0.70784908 | I112: =AVERAGE('Raw Data'!J112:J118) -> 0.70847125 | ... BB112: =AVERAGE('Raw Data'!BC112:BC118) -> #DIV/0! | BC112: =AVERAGE('Raw Data'!AV112:AV118) -> #DIV/0! | BD112: =AVERAGE('Raw Data'!AW112:AW118) -> #DIV/0! | BE112: =AVERAGE('Raw Data'!AX112:AX118) -> #DIV/0! | BF112: =AVERAGE('Raw Data'!AY112:AY118) -> #DIV/0!
A113: ='Raw Data'!A113 -> 112 | B113: =AVERAGE('Raw Data'!C113:C119) -> 0.70992276 | C113: =AVERAGE('Raw Data'!D113:D119) -> 0.70926405 | D113: =AVERAGE('Raw Data'!E113:E119) -> 0.71029455 | E113: =AVERAGE('Raw Data'!F113:F119) -> 0.70944997 | F113: =AVERAGE('Raw Data'!G113:G119) -> 0.70934191 | G113: =AVERAGE('Raw Data'!H113:H119) -> 0.70802207 | H113: =AVERAGE('Raw Data'!I113:I119) -> 0.70792269 | I113: =AVERAGE('Raw Data'!J113:J119) -> 0.70859293 | ... BB113: =AVERAGE('Raw Data'!BC113:BC119) -> #DIV/0! | BC113: =AVERAGE('Raw Data'!AV113:AV119) -> #DIV/0! | BD113: =AVERAGE('Raw Data'!AW113:AW119) -> #DIV/0! | BE113: =AVERAGE('Raw Data'!AX113:AX119) -> #DIV/0! | BF113: =AVERAGE('Raw Data'!AY113:AY119) -> #DIV/0!
A114: ='Raw Data'!A114 -> 113 | B114: =AVERAGE('Raw Data'!C114:C120) -> 0.71005219 | C114: =AVERAGE('Raw Data'!D114:D120) -> 0.7090976 | D114: =AVERAGE('Raw Data'!E114:E120) -> 0.71001984 | E114: =AVERAGE('Raw Data'!F114:F120) -> 0.70943968 | F114: =AVERAGE('Raw Data'!G114:G120) -> 0.70922866 | G114: =AVERAGE('Raw Data'!H114:H120) -> 0.70803346 | H114: =AVERAGE('Raw Data'!I114:I120) -> 0.70784075 | I114: =AVERAGE('Raw Data'!J114:J120) -> 0.70874534 | ... BB114: =AVERAGE('Raw Data'!BC114:BC120) -> #DIV/0! | BC114: =AVERAGE('Raw Data'!AV114:AV120) -> #DIV/0! | BD114: =AVERAGE('Raw Data'!AW114:AW120) -> #DIV/0! | BE114: =AVERAGE('Raw Data'!AX114:AX120) -> #DIV/0! | BF114: =AVERAGE('Raw Data'!AY114:AY120) -> #DIV/0!
A115: ='Raw Data'!A115 -> 114 | B115: =AVERAGE('Raw Data'!C115:C121) -> 0.71002197 | C115: =AVERAGE('Raw Data'!D115:D121) -> 0.70907605 | D115: =AVERAGE('Raw Data'!E115:E121) -> 0.70990066 | E115: =AVERAGE('Raw Data'!F115:F121) -> 0.70931555 | F115: =AVERAGE('Raw Data'!G115:G121) -> 0.70930563 | G115: =AVERAGE('Raw Data'!H115:H121) -> 0.70812565 | H115: =AVERAGE('Raw Data'!I115:I121) -> 0.70788845 | I115: =AVERAGE('Raw Data'!J115:J121) -> 0.70893625 | ... BB115: =AVERAGE('Raw Data'!BC115:BC121) -> #DIV/0! | BC115: =AVERAGE('Raw Data'!AV115:AV121) -> #DIV/0! | BD115: =AVERAGE('Raw Data'!AW115:AW121) -> #DIV/0! | BE115: =AVERAGE('Raw Data'!AX115:AX121) -> #DIV/0! | BF115: =AVERAGE('Raw Data'!AY115:AY121) -> #DIV/0!
A116: ='Raw Data'!A116 -> 115 | B116: =AVERAGE('Raw Data'!C116:C122) -> 0.71002582 | C116: =AVERAGE('Raw Data'!D116:D122) -> 0.70912057 | D116: =AVERAGE('Raw Data'!E116:E122) -> 0.70950877 | E116: =AVERAGE('Raw Data'!F116:F122) -> 0.70924528 | F116: =AVERAGE('Raw Data'!G116:G122) -> 0.70903907 | G116: =AVERAGE('Raw Data'!H116:H122) -> 0.70813378 | H116: =AVERAGE('Raw Data'!I116:I122) -> 0.7081283 | I116: =AVERAGE('Raw Data'!J116:J122) -> 0.70886754 | ... BB116: =AVERAGE('Raw Data'!BC116:BC122) -> #DIV/0! | BC116: =AVERAGE('Raw Data'!AV116:AV122) -> #DIV/0! | BD116: =AVERAGE('Raw Data'!AW116:AW122) -> #DIV/0! | BE116: =AVERAGE('Raw Data'!AX116:AX122) -> #DIV/0! | BF116: =AVERAGE('Raw Data'!AY116:AY122) -> #DIV/0!
A117: ='Raw Data'!A117 -> 116 | B117: =AVERAGE('Raw Data'!C117:C123) -> 0.71025082 | C117: =AVERAGE('Raw Data'!D117:D123) -> 0.70917008 | D117: =AVERAGE('Raw Data'!E117:E123) -> 0.70944954 | E117: =AVERAGE('Raw Data'!F117:F123) -> 0.70931472 | F117: =AVERAGE('Raw Data'!G117:G123) -> 0.70900165 | G117: =AVERAGE('Raw Data'!H117:H123) -> 0.70821075 | H117: =AVERAGE('Raw Data'!I117:I123) -> 0.70821496 | I117: =AVERAGE('Raw Data'!J117:J123) -> 0.70894362 | ... BB117: =AVERAGE('Raw Data'!BC117:BC123) -> #DIV/0! | BC117: =AVERAGE('Raw Data'!AV117:AV123) -> #DIV/0! | BD117: =AVERAGE('Raw Data'!AW117:AW123) -> #DIV/0! | BE117: =AVERAGE('Raw Data'!AX117:AX123) -> #DIV/0! | BF117: =AVERAGE('Raw Data'!AY117:AY123) -> #DIV/0!
A118: ='Raw Data'!A118 -> 117 | B118: =AVERAGE('Raw Data'!C118:C124) -> 0.71027405 | C118: =AVERAGE('Raw Data'!D118:D124) -> 0.70907813 | D118: =AVERAGE('Raw Data'!E118:E124) -> 0.70946945 | E118: =AVERAGE('Raw Data'!F118:F124) -> 0.70937642 | F118: =AVERAGE('Raw Data'!G118:G124) -> 0.70879071 | G118: =AVERAGE('Raw Data'!H118:H124) -> 0.70830695 | H118: =AVERAGE('Raw Data'!I118:I124) -> 0.70809595 | I118: =AVERAGE('Raw Data'!J118:J124) -> 0.70916357 | ... BB118: =AVERAGE('Raw Data'!BC118:BC124) -> #DIV/0! | BC118: =AVERAGE('Raw Data'!AV118:AV124) -> #DIV/0! | BD118: =AVERAGE('Raw Data'!AW118:AW124) -> #DIV/0! | BE118: =AVERAGE('Raw Data'!AX118:AX124) -> #DIV/0! | BF118: =AVERAGE('Raw Data'!AY118:AY124) -> #DIV/0!
A119: ='Raw Data'!A119 -> 118 | B119: =AVERAGE('Raw Data'!C119:C125) -> 0.71018936 | C119: =AVERAGE('Raw Data'!D119:D125) -> 0.70903857 | D119: =AVERAGE('Raw Data'!E119:E125) -> 0.70932546 | E119: =AVERAGE('Raw Data'!F119:F125) -> 0.70948518 | F119: =AVERAGE('Raw Data'!G119:G125) -> 0.70893496 | G119: =AVERAGE('Raw Data'!H119:H125) -> 0.70820776 | H119: =AVERAGE('Raw Data'!I119:I125) -> 0.70812086 | I119: =AVERAGE('Raw Data'!J119:J125) -> 0.70908686 | ... BB119: =AVERAGE('Raw Data'!BC119:BC125) -> #DIV/0! | BC119: =AVERAGE('Raw Data'!AV119:AV125) -> #DIV/0! | BD119: =AVERAGE('Raw Data'!AW119:AW125) -> #DIV/0! | BE119: =AVERAGE('Raw Data'!AX119:AX125) -> #DIV/0! | BF119: =AVERAGE('Raw Data'!AY119:AY125) -> #DIV/0!
... A501: ='Raw Data'!A501 -> 500 | B501: =AVERAGE('Raw Data'!C501:C507) -> #DIV/0! | C501: =AVERAGE('Raw Data'!D501:D507) -> #DIV/0! | D501: =AVERAGE('Raw Data'!E501:E507) -> #DIV/0! | E501: =AVERAGE('Raw Data'!F501:F507) -> #DIV/0! | F501: =AVERAGE('Raw Data'!G501:G507) -> #DIV/0! | G501: =AVERAGE('Raw Data'!H501:H507) -> #DIV/0! | H501: =AVERAGE('Raw Data'!I501:I507) -> #DIV/0! | I501: =AVERAGE('Raw Data'!J501:J507) -> #DIV/0! | ... BB501: =AVERAGE('Raw Data'!BC501:BC507) -> #DIV/0! | BC501: =AVERAGE('Raw Data'!AV501:AV507) -> #DIV/0! | BD501: =AVERAGE('Raw Data'!AW501:AW507) -> #DIV/0! | BE501: =AVERAGE('Raw Data'!AX501:AX507) -> #DIV/0! | BF501: =AVERAGE('Raw Data'!AY501:AY507) -> #DIV/0!

Sheet Intensity
A1: Measurement Number | B1: ='Raw Data'!B1 -> HART-14 | C1: ='Raw Data'!C1 -> HART-15 | D1: ='Raw Data'!D1 -> HART-13 | E1: ='Raw Data'!E1 -> HART-12 | F1: ='Raw Data'!F1 -> HART-16 | G1: ='Raw Data'!G1 -> HART-17 | H1: ='Raw Data'!H1 -> HART-18 | I1: ='Raw Data'!I1 -> HART-19 | ... BF1: ='Raw Data'!BF1 -> 0
A2: 1 | B2: 0.97785517 | C2: 0.11089902 | D2: 1.0044275 | E2: 0.12573461 | F2: 0.10903656 | G2: 0.24449145 | H2: 0.10930879 | I2: 0.20055032 | J2: 0.86920128 | K2: 0.20440704 | L2: 0.84856744 | M2: 0.55681662 | N2: 0.11471441 | O2: 0.76353862 | P2: 0.13029559 | Q2: 0.83968021 | R2: 0.63876929 | S2: 0.33703867 | T2: 0.12107706 | U2: 0.48781114 | V2: 0.29447183 | W2: 0.98446228 | X2: 0.66776349 | Y2: 0.36810027 | Z2: 0.15266607 | AA2: 1.0325717 | AB2: 0.64900838 | AC2: 0.10893112
A3: 2 | B3: 0.95785734 | C3: 0.1021795 | D3: 1.1100201 | E3: 0.13772572 | F3: 0.15526667 | G3: 0.40830439 | H3: 0.13310011 | I3: 0.18228454 | J3: 0.9202355 | K3: 0.18194905 | L3: 0.77256703 | M3: 0.50293383 | N3: 0.12662919 | O3: 1.3278836 | P3: 0.14118816 | Q3: 0.78570078 | R3: 0.65761996 | S3: 0.31411558 | T3: 0.11054938 | U3: 0.61712017 | V3: 0.44470095 | W3: 0.7746322 | X3: 0.68070518 | Y3: 0.49949086 | Z3: 0.14118649 | AA3: 0.80718336 | AB3: 0.64691743 | AC3: 0.47648666
A4: 3 | B4: 0.88127958 | C4: 0.11448965 | D4: 0.97165475 | E4: 0.13713836 | F4: 0.19511877 | G4: 0.48537399 | H4: 0.16781612 | I4: 0.17829314 | J4: 1.2840607 | K4: 0.1654371 | L4: 0.74728548 | M4: 0.62274381 | N4: 0.13444786 | O4: 0.881389 | P4: 0.14072403 | Q4: 0.72224728 | R4: 0.51515816 | S4: 0.23885622 | T4: 0.11095229 | U4: 0.79709817 | V4: 0.55261636 | W4: 0.69449419 | X4: 0.64414872 | Y4: 0.62948648 | Z4: 0.16297633 | AA4: 0.81087257 | AB4: 0.65606157 | AC4: 0.66979024
A5: 4 | B5: 0.91811207 | C5: 0.095541088 | D5: 0.88600993 | E5: 0.15840782 | F5: 0.23145452 | G5: 0.5020104 | H5: 0.18964591 | I5: 0.19119313 | J5: 1.559771 | K5: 0.15119974 | L5: 0.76798608 | M5: 0.65901117 | N5: 0.12999928 | O5: 0.98338986 | P5: 0.13490283 | Q5: 0.78402638 | R5: 0.2514897 | S5: 0.19548415 | T5: 0.11458855 | U5: 0.88410838 | V5: 0.53296409 | W5: 0.76632722 | X5: 0.66361321 | Y5: 0.66422044 | Z5: 0.14734642 | AA5: 0.89308756 | AB5: 0.65265277 | AC5: 0.72883715
A6: 5 | B6: 0.96825359 | C6: 0.071032488 | D6: 0.82593297 | E6: 0.16095459 | F6: 0.29653461 | G6: 0.47669221 | H6: 0.22957131 | I6: 0.25085515 | J6: 1.5285468 | K6: 0.14300091 | L6: 0.67938763 | M6: 0.66899154 | N6: 0.15275326 | O6: 0.91733918 | P6: 0.15832574 | Q6: 0.85989765 | R6: 0.13562932 | S6: 0.15044809 | T6: 0.10650412 | U6: 0.77587612 | V6: 0.63476135 | W6: 0.80913879 | X6: 0.66155172 | Y6: 0.65546014 | Z6: 0.14386679 | AA6: 0.88639159 | AB6: 0.72972348 | AC6: 0.9461242
A7: 6 | B7: 1.0981559 | C7: 0.089121466 | D7: 0.83767458 | E7: 0.15794266 | F7: 0.37628715 | G7: 0.46862726 | H7: 0.25782136 | I7: 0.25474794 | J7: 1.5392756 | K7: 0.14129229 | L7: 0.59550819 | M7: 0.67609917 | N7: 0.14856522 | O7: 0.81112263 | P7: 0.18493064 | Q7: 0.95099453 | R7: 0.092585571 | S7: 0.12012688 | T7: 0.10878106 | U7: 0.88395656 | V7: 0.71702139 | W7: 0.86904321 | X7: 0.67315941 | Y7: 0.73759633 | Z7: 0.13380004 | AA7: 0.87933178 | AB7: 0.78470451 | AC7: 0.89526234
A8: 7 | B8: 1.1288941 | C8: 0.094969894 | D8: 0.94362328 | E8: 0.16496598 | F8: 0.48627629 | G8: 0.46821665 | H8: 0.2905573 | I8: 0.21916175 | J8: 1.5027837 | K8: 0.15284229 | L8: 0.58710976 | M8: 0.67598266 | N8: 0.17374983 | O8: 0.65477408 | P8: 0.18901831 | Q8: 0.9441466 | R8: 0.07281955 | S8: 0.09439725 | T8: 0.115296 | U8: 1.0201417 | V8: 0.82293836 | W8: 0.87042354 | X8: 0.71904742 | Y8: 0.89771178 | Z8: 0.1524416 | AA8: 1.1791593 | AB8: 0.81698751 | AC8: 0.88613133
A9: 8 | B9: 1.1380475 | C9: 0.11131831 | D9: 1.0117926 | E9: 0.17994949 | F9: 0.6024533 | G9: 0.44298608 | H9: 0.31206728 | I9: 0.17550211 | J9: 1.4964652 | K9: 0.17689187 | L9: 0.77175828 | M9: 0.70877517 | N9: 0.18226928 | O9: 0.73794074 | P9: 0.19221359 | Q9: 0.88252206 | R9: 0.10996285 | S9: 0.088694956 | T9: 0.12233533 | U9: 1.1095958 | V9: 0.94211496 | W9: 0.94413911 | X9: 0.67979152 | Y9: 1.138089 | Z9: 0.19376252 | AA9: 1.2946617 | AB9: 0.8671033 | AC9: 0.71060618
A10: 9 | B10: 1.1282805 | C10: 0.1310702 | D10: 1.0898454 | E10: 0.17769417 | F10: 0.63799329 | G10: 0.39555128 | H10: 0.33729895 | I10: 0.16913106 | J10: 1.1368918 | K10: 0.2041471 | L10: 1.1525038 | M10: 0.74454857 | N10: 0.16640479 | O10: 0.7761986 | P10: 0.20005734 | Q10: 0.7397546 | R10: 0.25187382 | S10: 0.075959401 | T10: 0.12860318 | U10: 1.2196486 | V10: 1.0351865 | W10: 1.0750534 | X10: 0.66630111 | Y10: 1.2889098 | Z10: 0.17927272 | AA10: 1.3797388 | AB10: 0.96580719 | AC10: 0.63780019
A11: 10 | B11: 1.2423039 | C11: 0.1368735 | D11: 1.1609937 | E11: 0.19087253 | F11: 0.68406481 | G11: 0.35761607 | H11: 0.32995209 | I11: 0.18488795 | J11: 0.98588157 | K11: 0.19637049 | L11: 1.1603205 | M11: 0.89830756 | N11: 0.18454661 | O11: 0.77063909 | P11: 0.22640786 | Q11: 0.6641783 | R11: 0.3650625 | S11: 0.072748997 | T11: 0.13822659 | U11: 1.2640458 | V11: 1.0375315 | W11: 1.2095585 | X11: 0.70841435 | Y11: 1.4996614 | Z11: 0.17302406 | AA11: 1.5264253 | AB11: 1.0256752 | AC11: 0.67684646
A12: 11 | B12: 1.2363095 | C12: 0.15445749 | D12: 1.2623263 | E12: 0.20880808 | F12: 0.75624679 | G12: 0.36676536 | H12: 0.31572099 | I12: 0.20521791 | J12: 1.1629432 | K12: 0.19822339 | L12: 0.82182568 | M12: 1.0470672 | N12: 0.19116883 | O12: 0.8089508 | P12: 0.22976214 | Q12: 0.65168542 | R12: 0.30711322 | S12: 0.096446565 | T12: 0.15656088 | U12: 1.2059695 | V12: 0.98188571 | W12: 1.2638584 | X12: 0.7287243 | Y12: 1.4234441 | Z12: 0.16502233 | AA12: 1.4962263 | AB12: 1.0948485 | AC12: 0.76940412
A13: 12 | B13: 1.1537837 | C13: 0.16463225 | D13: 1.3256502 | E13: 0.21526274 | F13: 0.90319668 | G13: 0.38331285 | H13: 0.33106069 | I13: 0.24131171 | J13: 1.2468061 | K13: 0.24331655 | L13: 1.0687788 | M13: 1.0898499 | N13: 0.21188846 | O13: 0.90894895 | P13: 0.23571532 | Q13: 0.69523319 | R13: 0.33716143 | S13: 0.13062511 | T13: 0.16291706 | U13: 1.3094507 | V13: 0.91203101 | W13: 1.3610578 | X13: 0.77972413 | Y13: 1.3488511 | Z13: 0.15690528 | AA13: 1.2675685 | AB13: 1.2828012 | AC13: 0.79294858
... A204: 203 | B204: 1.9947129 | C204: 0.97036398 | D204: 2.704034 | E204: 1.1497987 | F204: 2.7003531 | G204: 1.4805316 | H204: 1.3764383 | I204: 0.51022942 | J204: 1.3278924 | K204: 1.9294776 | L204: 2.3036022 | M204: 1.050549 | N204: 1.2141738 | O204: 1.4433699 | P204: 1.4332775 | Q204: 1.0132715 | R204: 1.5167635 | S204: 1.5777238 | T204: 0.48196651 | U204: 1.9364699 | V204: 2.0503796 | W204: 1.4226332 | X204: 1.8921458 | Y204: 2.4053303 | Z204: 1.4962686 | AA204: 1.6282072 | AB204: 1.5516053 | AC204: 1.3389991
A205: 204 | B205: 1.8520792 | C205: 1.0728388 | D205: 2.6437128 | E205: 1.1992437 | F205: 2.7586549 | G205: 1.4504844 | H205: 1.3208454 | I205: 0.50499069 | K205: 1.9193074 | L205: 2.2730798 | M205: 1.062852 | N205: 1.1389678 | O205: 1.4455073 | P205: 1.5075078 | Q205: 1.0053903 | R205: 1.1237686 | S205: 1.6372523 | T205: 0.48049811 | U205: 2.2976086 | V205: 2.0263045 | W205: 1.4106197 | X205: 1.7590521 | Y205: 2.3752754 | Z205: 1.5341113 | AA205: 1.6622859 | AB205: 1.5278829 | AC205: 1.3738694
A206: 205 | B206: 1.808965 | C206: 1.224258 | D206: 2.4356334 | E206: 1.201643 | F206: 2.6935263 | G206: 1.4260204 | H206: 1.392296 | I206: 0.52014985 | K206: 1.9837269 | L206: 2.1698764 | M206: 1.0950636 | N206: 1.1547755 | O206: 1.4651531 | P206: 1.4473785 | Q206: 1.06301 | R206: 0.84901622 | S206: 1.7013548 | T206: 0.45906546 | U206: 2.5487513 | V206: 1.911381 | W206: 1.3798802 | X206: 1.7215486 | Y206: 2.4616859 | Z206: 1.5253109 | AA206: 1.778378 | AB206: 1.5800774 | AC206: 1.4055253
A207: 206 | B207: 1.8523301 | C207: 1.1901584 | D207: 2.3960363 | E207: 1.197505 | F207: 2.7879502 | G207: 1.4683421 | H207: 1.4725961 | I207: 0.5577735 | K207: 1.9784818 | L207: 2.09346 | M207: 1.1043041 | N207: 1.297343 | O207: 1.4249367 | P207: 1.4937088 | Q207: 1.1676948 | R207: 0.73540212 | S207: 1.8289454 | T207: 0.49827362 | U207: 2.4791851 | V207: 1.8924597 | W207: 1.3174977 | X207: 1.6554212 | Y207: 2.4720315 | Z207: 1.5511555 | AA207: 1.8633228 | AB207: 1.5954674 | AC207: 1.3891193
A208: 207 | B208: 1.7718894 | C208: 1.2218244 | D208: 2.4262783 | E208: 1.2045872 | F208: 2.8108091 | G208: 1.3554401 | H208: 1.4850927 | I208: 0.55730622 | K208: 1.8937544 | L208: 1.9558784 | M208: 1.1097609 | N208: 1.3930362 | O208: 1.4045415 | P208: 1.5881772 | Q208: 1.1373962 | R208: 0.72742904 | S208: 2.0218515 | T208: 0.54337146 | U208: 2.3467342 | V208: 2.1057438 | W208: 1.4271226 | X208: 1.6926902 | Y208: 2.4177902 | Z208: 1.5259224 | AA208: 1.9964278 | AB208: 1.6587095 | AC208: 1.4127941
A209: 208 | B209: 1.7029872 | C209: 1.2157889 | D209: 2.128896 | E209: 1.1792396 | F209: 2.36191 | G209: 1.3973038 | H209: 1.3619516 | I209: 0.5989271 | K209: 1.896013 | L209: 2.0693168 | M209: 1.0633386 | N209: 1.4041379 | O209: 1.3695866 | P209: 1.6962357 | Q209: 1.0792888 | R209: 0.75352287 | S209: 2.0502843 | T209: 0.4208746 | U209: 2.367241 | V209: 2.1294931 | W209: 1.5349977 | X209: 1.6777515 | Y209: 2.4249672 | Z209: 1.4866833 | AA209: 2.070072 | AB209: 1.6695605 | AC209: 1.3459816
A210: 209 | B210: 1.6094267 | C210: 1.2018969 | D210: 1.901295 | E210: 1.1924462 | F210: 1.8905184 | G210: 1.3301842 | H210: 1.4074958 | I210: 0.56764786 | K210: 2.0243523 | L210: 2.2282687 | M210: 1.0320585 | N210: 1.4909644 | O210: 1.2318046 | P210: 1.6755399 | Q210: 1.1627263 | R210: 0.72350406 | S210: 1.8740018 | T210: 0.30475286 | U210: 2.3813855 | V210: 1.8266056 | W210: 1.6730968 | X210: 1.6478814 | Y210: 2.3771487 | Z210: 1.4677512 | AA210: 2.1801539 | AB210: 1.7064312 | AC210: 1.291825
A211: 210 | B211: 1.507497 | C211: 1.2118366 | D211: 1.9307996 | E211: 1.1719008 | F211: 1.8871997 | G211: 1.2201939 | H211: 1.3855445 | I211: 0.52514907 | K211: 1.949287 | L211: 1.939323 | M211: 1.0318473 | N211: 1.4986732 | O211: 1.1803903 | P211: 1.6460178 | Q211: 1.1576657 | R211: 0.68741292 | S211: 1.8818682 | T211: 0.29219923 | U211: 2.3426309 | V211: 1.7488858 | W211: 1.6985994 | X211: 1.6405258 | Y211: 2.4302946 | Z211: 1.4869447 | AA211: 2.381821 | AB211: 1.7003461 | AC211: 1.3796201
A212: 211 | B212: 1.4225752 | C212: 1.2563679 | D212: 1.9063879 | E212: 1.1604904 | F212: 1.8558607 | G212: 1.237654 | H212: 1.3948491 | I212: 0.52034638 | K212: 2.1351052 | L212: 1.7943177 | M212: 1.0439827 | N212: 1.5808246 | O212: 1.2438698 | P212: 1.7327872 | Q212: 1.0498392 | R212: 0.58787899 | S212: 1.9298653 | T212: 0.28448667 | U212: 2.2781226 | V212: 1.6953505 | W212: 1.605413 | X212: 1.7883232 | Y212: 2.3424928 | Z212: 1.487266 | AA212: 2.3437207 | AB212: 1.759687 | AC212: 1.2947982
A213: 212 | B213: 1.4348858 | C213: 1.2666381 | D213: 1.9062024 | E213: 1.1779284 | F213: 2.0552996 | G213: 1.2511169 | H213: 1.4143817 | I213: 0.51206748 | K213: 2.5834942 | L213: 1.7470739 | M213: 1.0885972 | N213: 1.6587429 | O213: 1.2610624 | P213: 1.7676174 | Q213: 0.96582665 | R213: 0.47494577 | S213: 1.982716 | T213: 0.26550103 | U213: 2.393584 | V213: 1.7529098 | W213: 1.3579348 | X213: 1.7896442 | Y213: 2.2794124 | Z213: 1.4985123 | AA213: 2.4139419 | AB213: 1.7823571 | AC213: 1.2617206
A214: 213 | B214: 1.3943455 | C214: 1.2802321 | D214: 2.0403543 | E214: 1.1915239 | F214: 2.2066933 | G214: 1.3232408 | H214: 1.4495966 | I214: 0.50181045 | K214: 2.3866277 | L214: 1.6758135 | M214: 1.0847266 | N214: 1.5421098 | O214: 1.2506587 | P214: 1.6753531 | Q214: 0.96694418 | R214: 0.3692856 | S214: 1.9394909 | T214: 0.26854352 | U214: 2.5117307 | V214: 1.9714445 | W214: 1.2566078 | X214: 2.0321535 | Y214: 2.1961681 | Z214: 1.4605387 | AA214: 2.3550672 | AB214: 1.7254083 | AC214: 1.2708133
A215: 214 | B215: 1.3891883 | C215: 1.2767647 | D215: 1.9210793 | E215: 1.1832325 | F215: 2.1777362 | G215: 1.4275718 | H215: 1.4055994 | I215: 0.4835945 | K215: 2.4347138 | L215: 1.7458494 | M215: 1.0836648 | N215: 1.5213373 | O215: 1.2046215 | P215: 1.6390981 | Q215: 0.9710602 | R215: 0.25221794 | S215: 1.8727926 | T215: 0.25073925 | U215: 2.5000651 | V215: 2.1595896 | W215: 1.1301857 | X215: 2.2583336 | Y215: 2.2147704 | Z215: 1.4717843 | AA215: 2.498403 | AB215: 1.7360042 | AC215: 1.3303557
A216: 215 | B216: 1.4196954 | C216: 1.3872227 | D216: 2.0752384 | E216: 1.170865 | F216: 2.0892558 | G216: 1.5185465 | H216: 1.3823116 | I216: 0.47986751 | K216: 2.2722617 | L216: 1.8214005 | M216: 1.1766287 | N216: 1.5304164 | O216: 1.203198 | P216: 1.6271222 | Q216: 0.92847549 | R216: 0.20884428 | S216: 1.8505413 | T216: 0.25633558 | U216: 2.4511094 | V216: 1.9963242 | W216: 1.124005 | X216: 2.3404045 | Y216: 2.2693396 | Z216: 1.4131962 | AA216: 2.4952503 | AB216: 1.750094 | AC216: 1.3687228
... A221: 220 | B221: 1.3894893 | C221: 1.5008463 | D221: 2.124288 | E221: 1.4093022 | F221: 2.9971219 | G221: 1.5385278 | H221: 1.1908099 | I221: 0.49138953 | K221: 2.098622 | L221: 1.721356 | M221: 1.3580435 | N221: 1.5854261 | O221: 1.2299302 | P221: 1.6946755 | Q221: 1.324233 | R221: 0.10396822 | S221: 1.8673038 | T221: 0.21523882 | U221: 2.3588179 | V221: 1.630996 | W221: 1.3858154 | X221: 2.7498263 | Y221: 2.4318813 | Z221: 1.3582753 | AA221: 2.6784152 | AB221: 1.7685496 | AC221: 1.33114
A222: 221 | B222: 1.2891265 | C222: 1.4221438 | D222: 1.9871438 | E222: 1.3154234 | F222: 3.2101798 | G222: 1.6611583 | H222: 1.1092613 | I222: 0.51913805 | K222: 2.1602022 | L222: 1.7455216 | M222: 1.3796602 | N222: 1.7078915 | O222: 1.2685222 | P222: 1.6438682 | Q222: 1.2557637 | S222: 1.8578079 | T222: 0.22808887 | U222: 2.4923336 | V222: 1.6614203 | W222: 1.344015 | X222: 2.5434151 | Y222: 2.4916119 | Z222: 1.4231713 | AA222: 2.8186734 | AB222: 1.7506338 | AC222: 1.3420146
A223: 222 | B223: 1.2690046 | C223: 1.3709429 | D223: 1.6318022 | E223: 1.2824909 | F223: 3.3201468 | G223: 1.7527447 | H223: 1.0287785 | I223: 0.57277545 | K223: 2.0901661 | L223: 1.7929008 | M223: 1.4195503 | N223: 1.7117806 | O223: 1.3087754 | P223: 1.4624741 | Q223: 1.1966009 | S223: 1.8501988 | T223: 0.2238071 | U223: 2.8320318 | V223: 1.9216642 | W223: 1.3047191 | X223: 2.6530492 | Y223: 2.503633 | Z223: 1.4831147 | AA223: 2.8286462 | AB223: 1.7279411 | AC223: 1.3032208
A224: 223 | B224: 1.288971 | C224: 1.395718 | D224: 1.8151331 | E224: 1.2649281 | F224: 3.2331927 | G224: 1.8364672 | H224: 1.0444803 | I224: 0.56058274 | K224: 2.0782095 | L224: 1.8573249 | M224: 1.4235265 | N224: 1.6945407 | O224: 1.3504969 | P224: 1.3870373 | Q224: 1.142451 | S224: 1.8766887 | T224: 0.23161029 | U224: 2.5196318 | V224: 2.4967268 | W224: 1.2541147 | X224: 2.4172761 | Y224: 2.6082385 | Z224: 1.4942578 | AA224: 2.9197151 | AB224: 1.7449748 | AC224: 1.3240422
A225: 224 | B225: 1.3509068 | C225: 1.3383239 | D225: 2.0032556 | E225: 1.2772551 | F225: 3.1337416 | G225: 1.8330298 | H225: 1.0683155 | I225: 0.59482418 | K225: 2.177224 | L225: 1.859496 | M225: 1.4372127 | N225: 1.7011093 | O225: 1.4662475 | P225: 1.5061706 | Q225: 1.136417 | S225: 1.8253513 | T225: 0.26487764 | U225: 2.5497643 | V225: 2.4763021 | W225: 1.348718 | X225: 2.1897256 | Y225: 2.5519577 | Z225: 1.5896186 | AA225: 2.9590227 | AB225: 1.7855338 | AC225: 1.3717663
A226: 225 | B226: 1.3099389 | C226: 1.2400157 | D226: 2.0544159 | E226: 1.3368661 | F226: 2.7251258 | G226: 1.8074899 | H226: 1.1019963 | I226: 0.57716138 | K226: 2.2142905 | L226: 1.812477 | M226: 1.4068408 | N226: 1.7203219 | O226: 1.4754466 | P226: 1.478516 | Q226: 1.1080475 | S226: 1.7820417 | T226: 0.26410721 | U226: 2.6448546 | V226: 2.0829646 | W226: 1.236988 | X226: 2.0404036 | Y226: 2.4887123 | Z226: 1.6172575 | AA226: 2.9672349 | AB226: 1.7657745 | AC226: 1.4464962
A227: 226 | B227: 1.3597543 | C227: 1.1324396 | D227: 1.9468986 | E227: 1.3391147 | F227: 2.3544204 | G227: 1.6797928 | H227: 1.0833167 | I227: 0.56079726 | K227: 2.1551425 | L227: 1.7033226 | M227: 1.4151279 | N227: 1.7984088 | O227: 1.5271534 | P227: 1.6046713 | Q227: 1.1851891 | S227: 1.7544295 | T227: 0.21721905 | U227: 2.5175349 | V227: 1.9256724 | W227: 1.0732615 | X227: 2.2113401 | Y227: 2.4658761 | Z227: 1.707345 | AA227: 2.8828461 | AB227: 1.7685862 | AC227: 1.4245849
A228: 227 | B228: 1.2988887 | C228: 1.1172652 | D228: 1.9143779 | E228: 1.3589271 | F228: 2.1158096 | G228: 1.7591561 | H228: 1.1854517 | I228: 0.5755848 | K228: 2.1396222 | L228: 1.6177015 | M228: 1.5020081 | N228: 1.8152373 | O228: 1.4841149 | P228: 1.6235519 | Q228: 1.1936429 | S228: 1.760408 | T228: 0.18947368 | U228: 2.8319889 | V228: 1.7016762 | W228: 1.1587467 | X228: 2.3614448 | Y228: 2.3585852 | Z228: 1.7417289 | AA228: 2.9181573 | AB228: 1.7967516 | AC228: 1.3870463
A229: 228 | B229: 1.3143337 | C229: 1.1398908 | D229: 2.1633414 | E229: 1.3138141 | F229: 1.9357609 | G229: 1.6629099 | H229: 1.2560204 | I229: 0.56053553 | K229: 2.0546043 | L229: 1.5346914 | M229: 1.4852418 | N229: 1.7985237 | O229: 1.3590549 | P229: 1.7579044 | Q229: 1.2029304 | S229: 1.8437519 | T229: 0.17628347 | U229: 2.9695618 | V229: 1.6707359 | W229: 0.99996958 | X229: 2.4649656 | Y229: 2.3161221 | Z229: 1.8588618 | AA229: 2.8549273 | AB229: 1.8326292 | AC229: 1.4645725
A230: 229 | B230: 1.2882334 | C230: 1.1039302 | D230: 2.3881158 | E230: 1.3468031 | F230: 1.6580267 | G230: 1.44574 | H230: 1.3028329 | I230: 0.5376053 | K230: 2.1449056 | L230: 1.8469431 | M230: 1.5314233 | N230: 1.7649543 | O230: 1.3589125 | P230: 1.7593402 | Q230: 1.2687747 | S230: 1.8933807 | T230: 0.17661458 | U230: 2.8499781 | V230: 1.8338509 | W230: 0.93964312 | X230: 2.5460467 | Y230: 2.3699523 | Z230: 1.9764618 | AA230: 2.8924333 | AB230: 1.9080516 | AC230: 1.4773723
A231: 230 | B231: 1.2234068 | C231: 1.1335786 | D231: 2.2660321 | E231: 1.2595274 | F231: 1.6461085 | G231: 1.4083722 | H231: 1.4248501 | I231: 0.52012361 | K231: 2.1717367 | L231: 1.7510067 | M231: 1.590639 | N231: 1.8078 | O231: 1.330454 | P231: 1.6719545 | Q231: 1.3966315 | S231: 1.8987723 | T231: 0.19292527 | U231: 2.3934558 | V231: 2.0233383 | W231: 1.0495869 | X231: 2.2775368 | Y231: 2.4504184 | Z231: 1.9628748 | AA231: 2.8258216 | AB231: 1.8768076 | AC231: 1.6152113
A232: 231 | B232: 1.1257554 | C232: 1.0662128 | D232: 2.4381217 | E232: 1.2534527 | F232: 1.2999555 | G232: 1.5875644 | H232: 1.5015075 | I232: 0.52767639 | K232: 2.2016434 | L232: 1.4149861 | M232: 1.7034007 | N232: 1.7577036 | O232: 1.4171585 | P232: 1.5302058 | Q232: 1.6625219 | S232: 1.8756206 | T232: 0.20069794 | U232: 2.0941645 | V232: 2.0164778 | W232: 1.121667 | X232: 2.4614679 | Y232: 2.5245054 | Z232: 1.982144 | AA232: 2.8740753 | AB232: 1.8450092 | AC232: 1.6116473
A233: 232 | B233: 1.0802874 | C233: 1.0855868 | D233: 2.379949 | E233: 1.1779222 | F233: 1.0656219 | G233: 1.6249595 | H233: 1.4596534 | I233: 0.51987198 | K233: 2.2888764 | L233: 1.6234948 | M233: 1.6462061 | N233: 1.7312409 | O233: 1.4611683 | P233: 1.3608219 | Q233: 1.6999628 | S233: 1.8358812 | T233: 0.20349005 | U233: 2.1423047 | V233: 2.0200048 | W233: 1.2288399 | X233: 2.4475736 | Y233: 2.570823 | Z233: 2.012033 | AA233: 2.7926978 | AB233: 1.8109746 | AC233: 1.7060883
... A248: 247 | B248: 1.1338133 | C248: 1.3289305 | D248: 1.6893401 | E248: 1.4445198 | F248: 0.112365 | G248: 1.5490865 | H248: 1.8771208 | I248: 0.37920995 | K248: 2.9206002 | L248: 1.9830069 | M248: 1.8427905 | N248: 1.7121156 | O248: 1.5750561 | P248: 1.6119669 | Q248: 1.788468 | S248: 1.5676123 | T248: 0.13576974 | U248: 2.2116516 | V248: 1.8403566 | W248: 2.0591505 | X248: 2.5930473 | Y248: 2.8518457 | Z248: 2.0043484 | AA248: 2.7530241 | AB248: 1.5459053 | AC248: 2.2447452
...

Sheet Figures
A1: Distance from core | B1: JACK-35 | D1: HART-8 | M1: Distance from core | N1: Elson-26-6 | P1: C99-2-3 | R1: Marine | AA1: Elson-23-3 | AD1: NS water min | AE1: NS water max | AF1: NS average
A2: 0 | B2: 0.70975372 | C2: =AVERAGE(B2:B6) -> 0.70930566 | D2: 0.70948069 | E2: =AVERAGE(D2:D6) -> 0.70960011 | M2: 0 | N2: 0.70817736 | O2: =AVERAGE(N2:N6) -> 0.70768018 | P2: 0.70863095 | Q2: =AVERAGE(P2:P6) -> 0.70913171 | R2: 0.70918 | AA2: 0.71148507 | AB2: =AVERAGE(AA2:AA6) -> 0.71129027 | AD2: 0.7093 | AE2: 0.714305 | AF2: 0.711256
A3: 3 | B3: 0.7088805 | C3: =AVERAGE(B3:B7) -> 0.70920253 | D3: 0.70963318 | E3: =AVERAGE(D3:D7) -> 0.70964064 | M3: 3 | N3: 0.70670063 | O3: =AVERAGE(N3:N7) -> 0.70791984 | P3: 0.70975248 | Q3: =AVERAGE(P3:P7) -> 0.70931284 | R3: 0.70918 | AA3: 0.71349671 | AB3: =AVERAGE(AA3:AA7) -> 0.71061591 | AD3: 0.7093 | AE3: 0.714305 | AF3: 0.711256
A4: 6 | B4: 0.70899278 | C4: =AVERAGE(B4:B8) -> 0.70910194 | D4: 0.70980294 | E4: =AVERAGE(D4:D8) -> 0.70964743 | M4: 6 | N4: 0.7079258 | O4: =AVERAGE(N4:N8) -> 0.70818966 | P4: 0.70942019 | Q4: =AVERAGE(P4:P8) -> 0.70924881 | R4: 0.70918 | AA4: 0.7132432 | AB4: =AVERAGE(AA4:AA8) -> 0.70887214 | AD4: 0.7093 | AE4: 0.714305 | AF4: 0.711256
A5: 9 | B5: 0.70884382 | C5: =AVERAGE(B5:B9) -> 0.70915171 | D5: 0.70936751 | E5: =AVERAGE(D5:D9) -> 0.70961338 | M5: 9 | N5: 0.70828983 | O5: =AVERAGE(N5:N9) -> 0.70835595 | P5: 0.70868841 | Q5: =AVERAGE(P5:P9) -> 0.70906245 | R5: 0.70918 | AA5: 0.70345818 | AB5: =AVERAGE(AA5:AA9) -> 0.70821505 | AD5: 0.7093 | AE5: 0.714305 | AF5: 0.711256
A6: 12 | B6: 0.71005748 | C6: =AVERAGE(B6:B10) -> 0.70922542 | D6: 0.70971625 | E6: =AVERAGE(D6:D10) -> 0.70957597 | M6: 12 | N6: 0.70730726 | O6: =AVERAGE(N6:N10) -> 0.70841949 | P6: 0.70916653 | Q6: =AVERAGE(P6:P10) -> 0.70924957 | R6: 0.70918 | AA6: 0.71476819 | AB6: =AVERAGE(AA6:AA10) -> 0.71024102 | AD6: 0.7093 | AE6: 0.714305 | AF6: 0.711256
A7: 15 | B7: 0.70923809 | C7: =AVERAGE(B7:B11) -> 0.70908592 | D7: 0.70968334 | E7: =AVERAGE(D7:D11) -> 0.70955691 | M7: 15 | N7: 0.7093757 | O7: =AVERAGE(N7:N11) -> 0.70886137 | P7: 0.70953661 | Q7: =AVERAGE(P7:P11) -> 0.70919173 | R7: 0.70918 | AA7: 0.70811325 | AB7: =AVERAGE(AA7:AA11) -> 0.70814795 | AD7: 0.7093 | AE7: 0.714305 | AF7: 0.711256
